ERROR - 2023-05-20 17:55:49 --> Error connecting to the database: mysqli_sql_exception: No connection could be made because the target machine actively refused it in C:\xampp\htdocs\monitoring\vendor\codeigniter4\framework\system\Database\MySQLi\Connection.php:174
Stack trace:
#0 C:\xampp\htdocs\monitoring\vendor\codeigniter4\framework\system\Database\MySQLi\Connection.php(174): mysqli->real_connect('localhost', 'root', '', 'monitoring', 3306, '', 0)
#1 C:\xampp\htdocs\monitoring\vendor\codeigniter4\framework\system\Database\BaseConnection.php(391): CodeIgniter\Database\MySQLi\Connection->connect(false)
#2 C:\xampp\htdocs\monitoring\vendor\codeigniter4\framework\system\Database\BaseConnection.php(573): CodeIgniter\Database\BaseConnection->initialize()
#3 C:\xampp\htdocs\monitoring\vendor\codeigniter4\framework\system\Database\BaseBuilder.php(1616): CodeIgniter\Database\BaseConnection->query('SELECT *\nFROM `...', Array, false)
#4 C:\xampp\htdocs\monitoring\vendor\codeigniter4\framework\system\Model.php(268): CodeIgniter\Database\BaseBuilder->get()
#5 C:\xampp\htdocs\monitoring\vendor\codeigniter4\framework\system\BaseModel.php(656): CodeIgniter\Model->doFirst()
#6 C:\xampp\htdocs\monitoring\vendor\myth\auth\src\Authentication\LocalAuthenticator.php(140): CodeIgniter\BaseModel->first()
#7 C:\xampp\htdocs\monitoring\vendor\myth\auth\src\Authentication\LocalAuthenticator.php(19): Myth\Auth\Authentication\LocalAuthenticator->validate(Array, true)
#8 C:\xampp\htdocs\monitoring\vendor\myth\auth\src\Controllers\AuthController.php(87): Myth\Auth\Authentication\LocalAuthenticator->attempt(Array, false)
#9 C:\xampp\htdocs\monitoring\vendor\codeigniter4\framework\system\CodeIgniter.php(934): Myth\Auth\Controllers\AuthController->attemptLogin()
#10 C:\xampp\htdocs\monitoring\vendor\codeigniter4\framework\system\CodeIgniter.php(499): CodeIgniter\CodeIgniter->runController(Object(Myth\Auth\Controllers\AuthController))
#11 C:\xampp\htdocs\monitoring\vendor\codeigniter4\framework\system\CodeIgniter.php(368): CodeIgniter\CodeIgniter->handleRequest(NULL, Object(Config\Cache), false)
#12 C:\xampp\htdocs\monitoring\public\index.php(67): CodeIgniter\CodeIgniter->run()
#13 C:\xampp\htdocs\monitoring\vendor\codeigniter4\framework\system\Commands\Server\rewrite.php(47): require_once('C:\\xampp\\htdocs...')
#14 {main}

Next CodeIgniter\Database\Exceptions\DatabaseException: No connection could be made because the target machine actively refused it in C:\xampp\htdocs\monitoring\vendor\codeigniter4\framework\system\Database\MySQLi\Connection.php:218
Stack trace:
#0 C:\xampp\htdocs\monitoring\vendor\codeigniter4\framework\system\Database\BaseConnection.php(391): CodeIgniter\Database\MySQLi\Connection->connect(false)
#1 C:\xampp\htdocs\monitoring\vendor\codeigniter4\framework\system\Database\BaseConnection.php(573): CodeIgniter\Database\BaseConnection->initialize()
#2 C:\xampp\htdocs\monitoring\vendor\codeigniter4\framework\system\Database\BaseBuilder.php(1616): CodeIgniter\Database\BaseConnection->query('SELECT *\nFROM `...', Array, false)
#3 C:\xampp\htdocs\monitoring\vendor\codeigniter4\framework\system\Model.php(268): CodeIgniter\Database\BaseBuilder->get()
#4 C:\xampp\htdocs\monitoring\vendor\codeigniter4\framework\system\BaseModel.php(656): CodeIgniter\Model->doFirst()
#5 C:\xampp\htdocs\monitoring\vendor\myth\auth\src\Authentication\LocalAuthenticator.php(140): CodeIgniter\BaseModel->first()
#6 C:\xampp\htdocs\monitoring\vendor\myth\auth\src\Authentication\LocalAuthenticator.php(19): Myth\Auth\Authentication\LocalAuthenticator->validate(Array, true)
#7 C:\xampp\htdocs\monitoring\vendor\myth\auth\src\Controllers\AuthController.php(87): Myth\Auth\Authentication\LocalAuthenticator->attempt(Array, false)
#8 C:\xampp\htdocs\monitoring\vendor\codeigniter4\framework\system\CodeIgniter.php(934): Myth\Auth\Controllers\AuthController->attemptLogin()
#9 C:\xampp\htdocs\monitoring\vendor\codeigniter4\framework\system\CodeIgniter.php(499): CodeIgniter\CodeIgniter->runController(Object(Myth\Auth\Controllers\AuthController))
#10 C:\xampp\htdocs\monitoring\vendor\codeigniter4\framework\system\CodeIgniter.php(368): CodeIgniter\CodeIgniter->handleRequest(NULL, Object(Config\Cache), false)
#11 C:\xampp\htdocs\monitoring\public\index.php(67): CodeIgniter\CodeIgniter->run()
#12 C:\xampp\htdocs\monitoring\vendor\codeigniter4\framework\system\Commands\Server\rewrite.php(47): require_once('C:\\xampp\\htdocs...')
#13 {main}
CRITICAL - 2023-05-20 17:55:49 --> Unable to connect to the database.
Main connection [MySQLi]: No connection could be made because the target machine actively refused it
in SYSTEMPATH\Database\BaseConnection.php on line 427.
 1 SYSTEMPATH\Database\BaseConnection.php(573): CodeIgniter\Database\BaseConnection->initialize()
 2 SYSTEMPATH\Database\BaseBuilder.php(1616): CodeIgniter\Database\BaseConnection->query('SELECT *
FROM `users`
WHERE `username` = :username:
AND `users`.`deleted_at` IS NULL
 LIMIT 1', [...], false)
 3 SYSTEMPATH\Model.php(268): CodeIgniter\Database\BaseBuilder->get()
 4 SYSTEMPATH\BaseModel.php(656): CodeIgniter\Model->doFirst()
 5 VENDORPATH\myth\auth\src\Authentication\LocalAuthenticator.php(140): CodeIgniter\BaseModel->first()
 6 VENDORPATH\myth\auth\src\Authentication\LocalAuthenticator.php(19): Myth\Auth\Authentication\LocalAuthenticator->validate([...], true)
 7 VENDORPATH\myth\auth\src\Controllers\AuthController.php(87): Myth\Auth\Authentication\LocalAuthenticator->attempt([...], false)
 8 SYSTEMPATH\CodeIgniter.php(934): Myth\Auth\Controllers\AuthController->attemptLogin()
 9 SYSTEMPATH\CodeIgniter.php(499): CodeIgniter\CodeIgniter->runController(Object(Myth\Auth\Controllers\AuthController))
10 SYSTEMPATH\CodeIgniter.php(368): CodeIgniter\CodeIgniter->handleRequest(null, Object(Config\Cache), false)
11 FCPATH\index.php(67): CodeIgniter\CodeIgniter->run()
12 SYSTEMPATH\Commands\Server\rewrite.php(47): require_once('FCPATH\\index.php')
